Workbook

Sheet parameters
A1: Category | B1: Description | C1: Parameter | D1: Value | H1: usd to ntd
A2: Basic Settings | B2: 初始資金 (USD) | C2: Initial_Capital | D2: 100000000 | H2: 46104 | I2: 32.01
B3: 無風險日利率 (0.003%) | C3: risk_free_rate_daily | D3: 3e-05 | H3: 46105 | I3: 31.64
A4: Transaction Costs | B4: 股票手續費率 (0.1%) | C4: Stock_Comm_Rate | D4: 0.000399 | H4: 46106 | I4: 31.53
B5: 股票交易稅率 (0.3%) | C5: Stock_Tax_Rate | D5: 0.0015 | H5: 46107 | I5: 31.48
B6: 債券(有價)手續費率 | C6: Bond_Known_Comm_Rate | D6: 0.001 | H6: 46108 | I6: 31.48
B7: 債券(插值)手續費率 | C7: Bond_Interp_Comm_Rate | D7: 0.002 | H7: 46111 | I7: 31.6
C8: Bond_Comm_Rate_Default | D8: 0.001 | H8: 46112 | I8: 31.595
C9: Bond_Min_Comm_Default | D9: 5 | H9: 46113 | I9: 31.56
C10: Bond_Tax_Rate_Default | D10: 0 | H10: 46114 | I10: 31.58
H11: 46118 | I11: 31.9555
B12: 期貨手續費 (1個Tick) | C12: Future_Comm_Fixed | D12: 1_Tick | H12: 46119 | I12: 31.967
B13: 期貨交易稅率 | C13: Future_Tax_Rate | D13: 2e-05 | H13: 46120 | I13: 31.73
B14: 選擇權手續費 (1個Tick) | C14: Option_Comm_Fixed | D14: 1_Tick | H14: 46121 | I14: 31.725
B15: 選擇權交易稅率 | C15: Option_Tax_Rate | D15: 0.001 | H15: 46122 | I15: 31.33
H16: 46125 | I16: 31.405
H17: 46126 | I17: 31.65
A18: Risk & Margin Rules | B18: 股票放空保證金率 (90%) | C18: Stock_Short_Initial | D18: 0.9 | H18: 46127 | I18: 31.245
B19: 股票放空維持率 (130%) | C19: Stock_Short_Maint | D19: 1.3 | H19: 46128 | I19: 31.155
B20: 期貨原始保證金率 (7%) | C20: Future_Initial_Rate | D20: 0.07 | H20: 46129 | I20: 31.18
B21: 期貨維持保證金率 (5%) | C21: Future_Maint_Rate | D21: 0.05 | H21: 46132 | I21: 31.48
B22: 選擇權賣方原始保證金率 (10%) | C22: Option_Short_Initial | D22: 0.1 | E22: 此為舊規則，暫時保留 | H22: 46133 | I22: 31.45
B23: 選擇權賣方維持保證金率 (7%) | C23: Option_Short_Maint | D23: 0.07 | E23: 此為舊規則，暫時保留 | H23: 46134 | I23: 31.5
B24: 單一資產權重上限 (30%) | C24: Max_Single_Asset | D24: 0.3 | H24: 46135 | I24: 31.58
B25: 現金水位上限 (30%) | C25: Max_Cash_Position | D25: 0.3 | H25: 46136 | I25: 31.5
B26: 賣選擇權的保證金 | C26: Option_Short_Ratio | D26: 0.05 | E26: 新規則 | H26: 46139 | I26: 31.48
H27: 46140 | I27: 31.57
H28: 46141 | I28: 31.46
H29: 46142 | I29: 31.68
H30: 46146 | I30: 31.64
H31: 46147 | I31: 31.61
H32: 46148 | I32: 31.48
H33: 46149 | I33: 31.4
H34: 46150 | I34: 31.43
H35: 46153 | I35: 31.41
H36: 46154 | I36: 31.5
H37: 46155 | I37: 31.55
H38: 46156 | I38: 31.51
... H46: 46168 | I46: 31.51
H47: 46169
...

Sheet contract_specs
A1: ticker | B1: asset_class | C1: multiplier | D1: tick_value | E1: comm_rate | F1: min_comm | G1: tax_rate | H1: margin_rate | I1: margin_fixed | J1: strike_price | K1: option_type | L1: underlying | M1: exchange | N1: Description
A3: AAPL | B3: stock | C3: 1 | D3: 1 | E3: 0.002 | F3: 1 | G3: 0 | M3: NASDAQ | N3: 蘋果 (手續費0.2%, 低消$1, 免稅) | O3: 台股手續費2.8折
A4: 2454 | B4: stock | C4: 1 | E4: 0.000399 | G4: 0.003 | M4: TWSE | N4: 聯發科 | O4: 美股手續費0.0035/股
A5: 2449 | B5: stock | C5: 1 | E5: 0.000399 | G5: 0.003 | M5: TWSE | N5: 京元電
A6: 8064 | B6: stock | C6: 1 | E6: 0.000399 | G6: 0.003 | M6: TWSE | N6: 東捷
A7: 8086 | B7: stock | C7: 1 | E7: 0.000399 | G7: 0.003 | M7: TWSE | N7: 宏捷科
A8: 3711 | B8: stock | C8: 1 | E8: 0.000399 | G8: 0.003 | M8: TWSE | N8: 日月光
A9: 1582 | B9: stock | C9: 1 | E9: 0.000399 | G9: 0.003 | M9: TWSE | N9: 信錦
A10: 3450 | B10: stock | C10: 1 | E10: 0.000399 | G10: 0.003 | M10: TWSE | N10: 聯鈞
A11: 4916 | B11: stock | C11: 1 | E11: 0.000399 | G11: 0.003 | M11: TWSE | N11: 事欣科
A12: 2049 | B12: stock | C12: 1 | E12: 0.000399 | G12: 0.003 | M12: TWSE | N12: 上銀科技
A13: 3035 | B13: stock | C13: 1 | E13: 0.000399 | G13: 0.003 | M13: TWSE | N13: 智原
A14: 3406 | B14: stock | C14: 1 | E14: 0.000399 | G14: 0.003 | M14: TWSE | N14: 玉晶光
A15: RKLB | B15: stock | C15: 1 | E15: 5.1e-05 | G15: 0 | M15: NASDAQ | N15: 火箭實驗室
A16: LASR | B16: stock | C16: 1 | E16: 5.3e-05 | G16: 0 | M16: NASDAQ | N16: nLIGHT, Inc
A17: AR | B17: stock | C17: 1 | E17: 8.4e-05 | G17: 0 | M17: NASDAQ | N17: Antero Resources Corporation
A18: NTR | B18: stock | C18: 1 | E18: 4.8e-05 | G18: 0 | M18: NASDAQ | N18: Nutrien Ltd. (NTR)
A19: LUNR | B19: stock | C19: 1 | E19: 1.9e-05 | G19: 0 | M19: NASDAQ | N19: 直覺機器
A20: RRC | B20: stock | C20: 1 | E20: 8e-05 | G20: 0 | M20: NASDAQ | N20: 山脈資源
A21: AMSC | B21: stock | C21: 1 | E21: 1e-05 | G21: 0 | M21: NASDAQ | N21: 美國超導體
A22: SQM | B22: stock | C22: 1 | E22: 4.2e-05 | G22: 0 | M22: NASDAQ | N22: 智利化工礦
A23: ET | B23: stock | C23: 1 | E23: 0.000177 | G23: 0 | M23: NASDAQ | N23: 美國能源運輸
A24: GSAT | B24: stock | C24: 1 | E24: 4.8e-05 | G24: 0 | M24: NASDAQ | N24: Globalstar
A25: OII | B25: stock | C25: 1 | E25: 9.3e-05 | G25: 0 | M25: NASDAQ | N25: 國際海洋工程
A26: SLB | B26: stock | C26: 1 | E26: 6.6e-05 | G26: 0 | M26: NASDAQ | N26: 斯倫貝謝
... A36: CSIQ | B36: stock | C36: 1 | E36: 0.000181 | G36: 0 | M36: NASDAQ | N36: 加拿大阿特斯陽光電力
A37: SHLS | B37: stock | C37: 1 | E37: 0.000336 | G37: 0 | M37: NASDAQ
A38: OUST | B38: stock | C38: 1 | E38: 8.7e-05 | G38: 0 | M38: NASDAQ | N38: ouster inc
A39: US10Y | B39: bond | C39: 1 | F39: 0 | G39: 0 | M39: NASDAQ
A40: HY_BOND | B40: bond | C40: 1 | E40: 0.002 | N40: 高受益債
B41: future | C41: 200 | D41: 200 | F41: 50 | G41: 2e-05 | I41: 230000 | M41: TAIFEX
A42: TX | B42: future | C42: 20 | D42: 10 | F42: 100 | G42: 0 | I42: 300000 | M42: CME | N42: NASDAQ期貨
A43: ALI | B43: future | C43: 25 | D43: 0.25 | F43: 3.37 | G43: 0 | I43: 4000 | M43: CME
A44: GC | B44: future | C44: 100 | D44: 0.1 | F44: 3.37 | G44: 0 | I44: 32025 | M44: CME
A45: HG | B45: future | C45: 25000 | D45: 12.5 | E45: 5.85e-06 | G45: 0 | I45: 12000 | M45: CME | N45: ibkr broker 一口0.85$
A46: TXO_16000_P | B46: option | C46: 50 | D46: 50 | F46: 50 | G46: 0.001 | I46: 50000 | J46: 16000 | K46: put | L46: Index | M46: TAIFEX
A47: AAPL_180_C | B47: option | C47: 100 | D47: 50 | E47: 0 | F47: 30 | G47: 0 | I47: 0 | J47: 180 | K47: call | L47: Index | M47: CBOE

Sheet index
A1: date | B1: index_p | C1: TWSE | D1: SP
A2: 46104 | B2: 100 | C2: 32722.5 | D2: 6581 | E2: 100 | F2: 100
A3: 46105 | B3: =(1+(E3+F3)/2)*B2 -> 99.644393 | C3: 32612.24 | D3: 6556.37 | E3: =(C3-C2)/C2 -> -0.0033695469 | F3: =(D3-D2)/D2 -> -0.0037425923
A4: 46106 | B4: =(1+(E4+F4)/2)*B3 -> 101.17761 | C4: 33439.11 | D4: 6591.9 | E4: =(C4-C3)/C3 -> 0.025354591 | F4: =(D4-D3)/D3 -> 0.0054191572
A5: 46107 | B5: =(1+(E5+F5)/2)*B4 -> 99.913277 | C5: 33337.62 | D5: 6447.16 | E5: =(C5-C4)/C4 -> -0.0030350688 | F5: =(D5-D4)/D4 -> -0.021957251
A6: 46108 | B6: =(1+(E6+F6)/2)*B5 -> 98.969273 | C6: 33112.59 | D6: 6368.85 | E6: =(C6-C5)/C5 -> -0.0067500319 | F6: =(D6-D5)/D5 -> -0.012146433
A7: 46111 | B7: =(1+(E7+F7)/2)*B6 -> 97.885681 | C7: 32518.16 | D7: 6343.72 | E7: =(C7-C6)/C6 -> -0.017951782 | F7: =(D7-D6)/D6 -> -0.0039457673
A8: 46112 | B8: =(1+(E8+F8)/2)*B7 -> 98.114639 | C8: 31722.99 | D8: 6528.52 | E8: =(C8-C7)/C7 -> -0.024453106 | F8: =(D8-D7)/D7 -> 0.029131172
A9: 46113 | B9: =(1+(E9+F9)/2)*B8 -> 100.71146 | C9: 33174.82 | D9: 6575.32 | E9: =(C9-C8)/C8 -> 0.045765863 | F9: =(D9-D8)/D8 -> 0.0071685466
A10: 46114 | B10: =(1+(E10+F10)/2)*B9 -> 99.853539 | C10: 32572.43 | D10: 6582.69 | E10: =(C10-C9)/C9 -> -0.018158049 | F10: =(D10-D9)/D9 -> 0.001120858
A11: 46118 | B11: =(1+(E11+F11)/2)*B10 -> 100.07455 | C11: 32572.43 | D11: 6611.83 | E11: =(C11-C10)/C10 -> 0 | F11: =(D11-D10)/D10 -> 0.0044267617
A12: 46119 | B12: =(1+(E12+F12)/2)*B11 -> 101.12242 | C12: 33229.82 | D12: 6616.85 | E12: =(C12-C11)/C11 -> 0.020182406 | F12: =(D12-D11)/D11 -> 0.00075924517
A13: 46120 | B13: =(1+(E13+F13)/2)*B12 -> 104.72093 | C13: 34761.38 | D13: 6782.81 | E13: =(C13-C12)/C12 -> 0.046089928 | F13: =(D13-D12)/D12 -> 0.025081421
A14: 46121 | B14: =(1+(E14+F14)/2)*B13 -> 105.19429 | C14: 34861.16 | D14: 6824.66 | E14: =(C14-C13)/C13 -> 0.0028704269 | F14: =(D14-D13)/D13 -> 0.0061700092
... A47: 46168 | B47: =(1+(E47+F47)/2)*B46 -> 123.54654 | C47: 43525.37 | D47: 7519.12 | E47: =(C47-C46)/C46 -> -0.0027272686 | F47: =(D47-D46)/D46 -> 0.0061082737

Sheet 績效淨值
B1: 台股GMV | C1: 美股GMV | D1: 股票變動 | E1: 期貨變動 | F1: 股票累積手續費 | G1: 期貨累積手續費 | H1: 綜合累積手續費 | I1: 稅 | J1: 股利收入 | K1: 股利累積收入 | L1: 淨值 | M1: 程式淨值 | N1: 差額 | O1: 東捷佔比
A2: 46104 | B2: =stock!Z2*stock_position!BF2+stock!AF2*stock_position!BR2+stock!AG2*stock_position!AX3+stock!AB2*stock_position!BJ3+stock!AH2*stock_position!AZ3 -> 51641459 | C2: =stock!B2*stock_position!B2+stock!C2*stock_position!D2+stock!D2*stock_position!F2+stock!E2*stock_position!H2+stock!F2*stock_position!J2+stock!N2*stock_position!Z2 -> 40819526 | D2: =(B2+C2)-F$213 -> 810357.4 | E2: =(futures!E2-futures_position!$I$2)*100*100 -> -427000 | F2: =L75 -> 22938.65 | G2: 337 | H2: =G2+F2 -> 23275.65 | I2: 0 | L2: =E$213+D2+E2-H2-I2 -> 1.0036008e+08 | M2: =B75 -> 1.0036008e+08 | N2: =L2-M2 -> 0.35279286 | O2: =stock!AG2*stock_position!AX2/M2 -> 0.16903986
A3: 46105 | B3: =stock!Z3*stock_position!BF3+stock!AF3*stock_position!BR3+stock!AG3*stock_position!AX4+stock!AB3*stock_position!BJ4+stock!AH3*stock_position!AZ4 -> 50531586 | C3: =stock!B3*stock_position!B3+stock!C3*stock_position!D3+stock!D3*stock_position!F3+stock!E3*stock_position!H3+stock!F3*stock_position!J3+stock!N3*stock_position!Z3 -> 40888427 | D3: =(B3+C3)-F$213 -> -230615.17 | E3: =(futures!E3-futures_position!$I$2)*100*100 -> 1340000 | F3: =L76 -> 22938.65 | G3: 337 | H3: =G3+F3 -> 23275.65 | I3: 0 | L3: =E$213+D3+E3-H3-I3 -> 1.0108611e+08 | M3: =B76 -> 1.0108611e+08 | N3: =L3-M3 -> 0.23579013 | O3: =stock!AG3*stock_position!AX3/M3 -> 0.15491987
A4: 46106 | B4: =stock!Z4*stock_position!BF4+stock!AF4*stock_position!BR4+stock!AG4*stock_position!AX5+stock!AB4*stock_position!BJ5+stock!AH4*stock_position!AZ5 -> 52715789 | C4: =stock!B4*stock_position!B4+stock!C4*stock_position!D4+stock!D4*stock_position!F4+stock!E4*stock_position!H4+stock!F4*stock_position!J4+stock!N4*stock_position!Z4 -> 42907124 | D4: =(B4+C4)-F$213 -> 3972284.6 | E4: =(futures!E4-futures_position!$I$2)*100*100 -> 855000 | F4: =L77 -> 22938.65 | G4: 337 | H4: =G4+F4 -> 23275.65 | I4: 0 | L4: =E$213+D4+E4-H4-I4 -> 104804009 | M4: =B77 -> 1.0480401e+08 | N4: =L4-M4 -> 0.23230256 | O4: =stock!AG4*stock_position!AX4/M4 -> 0.15783729
A5: 46107 | B5: =stock!Z5*stock_position!BF5+stock!AF5*stock_position!BR5+stock!AG5*stock_position!AX6+stock!AB5*stock_position!BJ6+stock!AH5*stock_position!AZ6 -> 54391057 | C5: =stock!B5*stock_position!B5+stock!C5*stock_position!D5+stock!D5*stock_position!F5+stock!E5*stock_position!H5+stock!F5*stock_position!J5+stock!N5*stock_position!Z5 -> 40751210 | D5: =(B5+C5)-F$213 -> 3491638.6 | E5: =(futures!E5-futures_position!$I$2)*100*100 -> -92000 | F5: =L78 -> 22938.65 | G5: 337 | H5: =G5+F5 -> 23275.65 | I5: 0 | L5: =E$213+D5+E5-H5-I5 -> 1.0337636e+08 | M5: =B78 -> 1.0337636e+08 | N5: =L5-M5 -> 0.23068614 | O5: =stock!AG5*stock_position!AX5/M5 -> 0.17606263
A6: 46108 | B6: =stock!Z6*stock_position!BF6+stock!AF6*stock_position!BR6+stock!AG6*stock_position!AX7+stock!AB6*stock_position!BJ7+stock!AH6*stock_position!AZ7 -> 53040319 | C6: =stock!B6*stock_position!B6+stock!C6*stock_position!D6+stock!D6*stock_position!F6+stock!E6*stock_position!H6+stock!F6*stock_position!J6+stock!N6*stock_position!Z6 -> 40005673 | D6: =(B6+C6)-F$213 -> 1395364.2 | E6: =(futures!E6-futures_position!$I$2)*100*100 -> 586000 | F6: =L79 -> 22938.65 | G6: 337 | H6: =G6+F6 -> 23275.65 | I6: 0 | L6: =E$213+D6+E6-H6-I6 -> 1.0195809e+08 | M6: =B79 -> 101958088 | N6: =L6-M6 -> 0.57547647 | O6: =stock!AG6*stock_position!AX6/M6 -> 0.16871389
A7: 46109 | C7: =D124 | F7: =L80 | I7: =O80 | M7: =B80
A8: 46110 | C8: =D125 | F8: =L81 | I8: =O81 | M8: =B81
A9: 46111 | B9: =stock!AF7*stock_position!BR2+stock!AG7*stock_position!AX2+stock!AB7*stock_position!BJ2+stock!AH7*stock_position!AZ2+stock!AA7*stock_position!BH7 -> 50785177 | C9: =stock!D7*stock_position!F7+stock!E7*stock_position!H7+stock!N7*stock_position!Z7+stock!F7*stock_position!J7+stock!O7*stock_position!AB7+stock!I7*stock_position!P7+stock!G7*stock_position!L7 -> 39051000 | D9: =(B9+C9)-F$220 -> -1683002 | E9: =(futures!E7-futures_position!$I$2)*100*100 -> 1903000 | F9: =L82 -> 32312.35 | G9: 337 | H9: =G9+F9 -> 32649.35 | I9: =O82 -> 28714.68 | L9: =E$213+D9+E9-H9-I9 -> 100158634 | M9: =B82 -> 100158634 | N9: =L9-M9 -> -0.030000001 | O9: =stock!AG7*stock_position!AX7/M9 -> 0.16164152
A10: 46112 | B10: =stock!AF8*stock_position!BR3+stock!AG8*stock_position!AX3+stock!AB8*stock_position!BJ3+stock!AH8*stock_position!AZ3+stock!AA8*stock_position!BH8 -> 48197084 | C10: =stock!D8*stock_position!F8+stock!E8*stock_position!H8+stock!N8*stock_position!Z8+stock!F8*stock_position!J8+stock!O8*stock_position!AB8+stock!I8*stock_position!P8+stock!G8*stock_position!L8 -> 39283901 | D10: =(B10+C10)-F$220 -> -4038195.1 | E10: =(futures!E8-futures_position!$I$2)*100*100 -> 3156000 | F10: =L83 -> 32312.35 | G10: 337 | H10: =G10+F10 -> 32649.35 | I10: =O83 -> 28714.68 | L10: =E$213+D10+E10-H10-I10 -> 99056441 | M10: =B83 -> 99056441 | N10: =L10-M10 -> -0.10788856 | O10: =stock!AG8*stock_position!AX8/M10 -> 0.15513336
A11: 46113 | B11: =stock!AF9*stock_position!BR4+stock!AG9*stock_position!AX4+stock!AB9*stock_position!BJ4+stock!AH9*stock_position!AZ4+stock!AA9*stock_position!BH9 -> 51281022 | C11: =stock!D9*stock_position!F9+stock!E9*stock_position!H9+stock!N9*stock_position!Z9+stock!F9*stock_position!J9+stock!O9*stock_position!AB9+stock!I9*stock_position!P9+stock!G9*stock_position!L9 -> 39087133 | D11: =(B11+C11)-F$220 -> -1151023.7 | E11: =(futures!E9-futures_position!$I$2)*100*100 -> 1651000 | F11: =L84 -> 32312.35 | G11: 337 | H11: =G11+F11 -> 32649.35 | I11: =O84 -> 28714.68 | L11: =E$213+D11+E11-H11-I11 -> 1.0043861e+08 | M11: =B84 -> 100438612 | N11: =L11-M11 -> 0.29715101 | O11: =stock!AG9*stock_position!AX9/M11 -> 0.15607185
A12: 46114 | B12: =stock!AF10*stock_position!BR5+stock!AG10*stock_position!AX5+stock!AB10*stock_position!BJ5+stock!AH10*stock_position!AZ5+stock!AA10*stock_position!BH10 -> 50711210 | C12: =stock!D10*stock_position!F10+stock!E10*stock_position!H10+stock!N10*stock_position!Z10+stock!F10*stock_position!J10+stock!O10*stock_position!AB10+stock!I10*stock_position!P10+stock!G10*stock_position!L10 -> 39919332 | D12: =(B12+C12)-F$220 -> -888637.05 | E12: =(futures!E10-futures_position!$I$2)*100*100 -> 2527000 | F12: =L85 -> 32312.35 | G12: 337 | H12: =G12+F12 -> 32649.35 | I12: =O85 -> 28714.68 | L12: =E$213+D12+E12-H12-I12 -> 1.01577e+08 | M12: =B85 -> 101576999 | N12: =L12-M12 -> -0.079156324 | O12: =stock!AG10*stock_position!AX10/M12 -> 0.15781162
A13: 46115 | C13: =D130 | F13: =L86 | I13: =O86 | M13: =B86
A14: 46116 | C14: =D131 | F14: =L87 | I14: =O87 | M14: =B87
A15: 46117 | B15: =C132 | C15: =D132 | I15: =O88 | M15: =B88
A16: 46118 | B16: =stock!AF11*stock_position!BR2+stock!AG11*stock_position!AX2+stock!AB11*stock_position!BJ2+stock!AH11*stock_position!AZ2+stock!AA11*stock_position!BH7 -> 50711210 | C16: =stock!D11*stock_position!F11+stock!E11*stock_position!H11+stock!N11*stock_position!Z11+stock!F11*stock_position!J11+stock!O11*stock_position!AB11+stock!I11*stock_position!P11+stock!G11*stock_position!L11 -> 39618741 | D16: =(B16+C16)-F$227 -> -1189228.2 | E16: =(futures!E11-futures_position!$I$2)*100*100 -> 2320000 | F16: =H16-G16 -> 32312.35 | G16: 337 | H16: 32649.35 | I16: =O89 -> 28714.68 | L16: =E$213+D16+E16-H16-I16 -> 1.0106941e+08 | M16: =B89 -> 101069408 | N16: =L16-M16 -> -0.21915634 | O16: =stock!AG11*stock_position!AX11/M16 -> 0.15860419
A17: 46119 | B17: =stock!AF12*stock_position!BR3+stock!AG12*stock_position!AX3+stock!AB12*stock_position!BJ3+stock!AH12*stock_position!AZ3+stock!AA12*stock_position!BH8 -> 50320634 | C17: =stock!D12*stock_position!F12+stock!E12*stock_position!H12+stock!N12*stock_position!Z12+stock!F12*stock_position!J12+stock!O12*stock_position!AB12+stock!I12*stock_position!P12+stock!G12*stock_position!L12 -> 39344496 | D17: =(B17+C17)-F$227 -> -1854049.2 | E17: =(futures!E12-futures_position!$I$2)*100*100 -> 3859000 | F17: =H17-G17 -> 32312.35 | G17: 337 | H17: 32649.35 | I17: =O90 -> 28714.68 | L17: =E$213+D17+E17-H17-I17 -> 1.0194359e+08 | M17: =B90 -> 101943587 | N17: =L17-M17 -> -0.27479838 | O17: =stock!AG12*stock_position!AX12/M17 -> 0.15251613
A18: 46120 | B18: =stock!AF13*stock_position!BR4+stock!AG13*stock_position!AX4+stock!AB13*stock_position!BJ4+stock!AH13*stock_position!AZ4+stock!AA13*stock_position!BH9 -> 52947205 | C18: =stock!D13*stock_position!F13+stock!E13*stock_position!H13+stock!N13*stock_position!Z13+stock!F13*stock_position!J13+stock!O13*stock_position!AB13+stock!I13*stock_position!P13+stock!G13*stock_position!L13 -> 39658168 | D18: =(B18+C18)-F$227 -> 1086194 | E18: =(futures!E13-futures_position!$I$2)*100*100 -> 2897000 | F18: =H18-G18 -> 32312.35 | G18: 337 | H18: 32649.35 | I18: =O91 -> 28714.68 | L18: =E$213+D18+E18-H18-I18 -> 1.0392183e+08 | M18: =B91 -> 103921830 | N18: =L18-M18 -> -0.066094533 | O18: =stock!AG13*stock_position!AX13/M18 -> 0.1656173
A19: 46121 | B19: =stock!AF14*stock_position!BR5+stock!AG14*stock_position!AX5+stock!AB14*stock_position!BJ5+stock!AH14*stock_position!AZ5+stock!AA14*stock_position!BH10 -> 55194650 | C19: =stock!D14*stock_position!F14+stock!E14*stock_position!H14+stock!N14*stock_position!Z14+stock!F14*stock_position!J14+stock!O14*stock_position!AB14+stock!I14*stock_position!P14+stock!G14*stock_position!L14 -> 39338805 | D19: =(B19+C19)-F$227 -> 3014275.5 | E19: =(futures!E14-futures_position!$I$2)*100*100 -> 3271000 | F19: =H19-G19 -> 32312.35 | G19: 337 | H19: 32649.35 | I19: =O92 -> 28714.68 | L19: =E$213+D19+E19-H19-I19 -> 1.0622391e+08 | M19: =B92 -> 106223912 | N19: =L19-M19 -> -0.54546161 | O19: =stock!AG14*stock_position!AX14/M19 -> 0.17821342
A20: 46122 | B20: =stock!AF15*stock_position!BR6+stock!AG15*stock_position!AX6+stock!AB15*stock_position!BJ6+stock!AH15*stock_position!AZ6+stock!AA15*stock_position!BH11 -> 55722562 | C20: =stock!D15*stock_position!F15+stock!E15*stock_position!H15+stock!N15*stock_position!Z15+stock!F15*stock_position!J15+stock!O15*stock_position!AB15+stock!I15*stock_position!P15+stock!G15*stock_position!L15 -> 40014901 | D20: =(B20+C20)-F$227 -> 4218284 | E20: =(futures!E15-futures_position!$I$2)*100*100 -> 3210000 | F20: =H20-G20 -> 32312.35 | G20: 337 | H20: 32649.35 | I20: =O93 -> 28714.68 | L20: =E$213+D20+E20-H20-I20 -> 1.0736692e+08 | M20: =B93 -> 107366920 | N20: =L20-M20 -> -0.076205522 | O20: =stock!AG15*stock_position!AX15/M20 -> 0.17739904
A21: 46123 | B21: =C138 | C21: =D138 | F21: =L94 | I21: =O94 | M21: =B94
A22: 46124 | B22: =C139 | C22: =D139 -> 賣出期貨損益 | D22: =G95 -> 5742500 | E22: 買入期貨 | F22: 3600000 | G22: 結算獲利 | H22: =D22-G234 -> 2142500 | M22: =B95
A23: 46125 | B23: =stock!AG16*stock_position!AX2+stock!AB16*stock_position!BJ2+stock!AH16*stock_position!AZ2+stock!AA16*stock_position!BH7+stock!AC16*stock_position!BN16 -> 58406274 | C23: =stock!E16*stock_position!H16+stock!N16*stock_position!Z16+stock!F16*stock_position!J16+stock!O16*stock_position!AB16+stock!I16*stock_position!P16+stock!G16*stock_position!L16+stock!H16*stock_position!N16 -> 40377092 | D23: =(B23+C23)-F$234 -> 9754180.8 | E23: =(futures!F16-futures_position!$K$16)*300*25000 -> 1533750 | F23: =L96 -> 40613.31 | G23: 4424 | H23: =G23+F23 -> 45037.31 | I23: =O96 -> 57572.09 | L23: =E$213+D23+E23-H23-I23 -> 1.1118532e+08 | M23: =B96 -> 111185322 | N23: =L23-M23 -> -0.56159149 | O23: =stock!AG16*stock_position!AX16/M23 -> 0.18232003
A24: 46126 | B24: =stock!AG17*stock_position!AX3+stock!AB17*stock_position!BJ3+stock!AH17*stock_position!AZ3+stock!AA17*stock_position!BH8+stock!AC17*stock_position!BN17 -> 56114089 | C24: =stock!E17*stock_position!H17+stock!N17*stock_position!Z17+stock!F17*stock_position!J17+stock!O17*stock_position!AB17+stock!I17*stock_position!P17+stock!G17*stock_position!L17+stock!H17*stock_position!N17 -> 40561066 | D24: =(B24+C24)-F$234 -> 7645968.9 | E24: =(futures!F17-futures_position!$K$16)*300*25000 -> 2145000 | F24: =L97 -> 40613.31 | G24: 4424 | H24: =G24+F24 -> 45037.31 | I24: =O97 -> 57572.09 | L24: =E$213+D24+E24-H24-I24 -> 1.0968836e+08 | M24: =B97 -> 109688360 | N24: =L24-M24 -> -0.5186132 | O24: =stock!AG17*stock_position!AX17/M24 -> 0.16747019
A25: 46127 | B25: =stock!AG18*stock_position!AX4+stock!AB18*stock_position!BJ4+stock!AH18*stock_position!AZ4+stock!AA18*stock_position!BH9+stock!AC18*stock_position!BN18 -> 58240569 | C25: =stock!E18*stock_position!H18+stock!N18*stock_position!Z18+stock!F18*stock_position!J18+stock!O18*stock_position!AB18+stock!I18*stock_position!P18+stock!G18*stock_position!L18+stock!H18*stock_position!N18 -> 40454707 | D25: =(B25+C25)-F$234 -> 9666090.1 | E25: =(futures!F18-futures_position!$K$16)*300*25000 -> 2317500 | F25: =L98 -> 40613.31 | G25: 4424 | H25: =G25+F25 -> 45037.31 | I25: =O98 -> 57572.09 | L25: =E$213+D25+E25-H25-I25 -> 1.1188098e+08 | M25: =B98 -> 111880981 | N25: =L25-M25 -> -0.29273601 | O25: =stock!AG18*stock_position!AX18/M25 -> 0.16478045
A26: 46128 | B26: =stock!AG19*stock_position!AX5+stock!AB19*stock_position!BJ5+stock!AH19*stock_position!AZ5+stock!AA19*stock_position!BH10+stock!AC19*stock_position!BN19 -> 58665676 | C26: =stock!E19*stock_position!H19+stock!N19*stock_position!Z19+stock!F19*stock_position!J19+stock!O19*stock_position!AB19+stock!I19*stock_position!P19+stock!G19*stock_position!L19+stock!H19*stock_position!N19 -> 42154430 | D26: =(B26+C26)-F$234 -> 11790920 | E26: =(futures!F19-futures_position!$K$16)*300*25000 -> 1691250 | F26: =L99 -> 40613.31 | G26: 4424 | H26: =G26+F26 -> 45037.31 | I26: =O99 -> 57572.09 | L26: =E$213+D26+E26-H26-I26 -> 1.1337956e+08 | M26: =B99 -> 113379561 | N26: =L26-M26 -> -0.20890525 | O26: =stock!AG19*stock_position!AX19/M26 -> 0.16350649
A27: 46129 | B27: =stock!AG20*stock_position!AX6+stock!AB20*stock_position!BJ6+stock!AH20*stock_position!AZ6+stock!AA20*stock_position!BH11+stock!AC20*stock_position!BN20 -> 59905900 | C27: =stock!E20*stock_position!H20+stock!N20*stock_position!Z20+stock!F20*stock_position!J20+stock!O20*stock_position!AB20+stock!I20*stock_position!P20+stock!G20*stock_position!L20+stock!H20*stock_position!N20 -> 41717826 | D27: =(B27+C27)-F$234 -> 12594541 | E27: =(futures!F20-futures_position!$K$16)*300*25000 -> 2043750 | F27: =L100 -> 40613.31 | G27: 4424 | H27: =G27+F27 -> 45037.31 | I27: =O100 -> 57572.09 | L27: =E$213+D27+E27-H27-I27 -> 1.1453568e+08 | M27: =B100 -> 114535682 | N27: =L27-M27 -> -0.3529088 | O27: =stock!AG20*stock_position!AX20/M27 -> 0.16752524
A28: 46130 | B28: =C145 | C28: =D145 -> 1.0162373e+08 | F28: =L101 | I28: =O101 | M28: =B101
A29: 46131 | B29: =C146 | C29: =D146 | F29: =L102 | I29: =O102 | M29: =B102
A30: 46132 | B30: =stock!AG21*stock_position!AX21+stock!AB21*stock_position!BJ21+stock!AH21*stock_position!AZ21+stock!AC21*stock_position!BN21+stock!AD21*stock_position!BL21 -> 62124633 | C30: =stock!N21*stock_position!Z21+stock!O21*stock_position!AB21+stock!I21*stock_position!P21+stock!J21*stock_position!R21+stock!K21*stock_position!T21+stock!P21*stock_position!AD21+stock!Q21*stock_position!AF21+stock!L21*stock_position!V21 -> 41641396 | D30: =(B30+C30)-F$241 -> 22894637 | E30: =(futures!F21-futures_position!$K$16)*300*25000 -> 1762500 | F30: =L103 -> 52221.79 | G30: 4424 | H30: =G30+F30 -> 56645.79 | I30: =O103 -> 85044.73 | L30: =E$213+B30+C30-(F$213-2659617.98)+E30-H30-I30 -> 1.1639583e+08 | M30: =B103 -> 1.1639583e+08 | N30: =L30-M30 -> 0.0021219403 | O30: =stock!AG21*stock_position!AX21/M30 -> 0.17479012
A31: 46133 | B31: =stock!AG22*stock_position!AX22+stock!AB22*stock_position!BJ22+stock!AH22*stock_position!AZ22+stock!AC22*stock_position!BN22+stock!AD22*stock_position!BL22 -> 62043123 | C31: =stock!N22*stock_position!Z22+stock!O22*stock_position!AB22+stock!I22*stock_position!P22+stock!J22*stock_position!R22+stock!K22*stock_position!T22+stock!P22*stock_position!AD22+stock!Q22*stock_position!AF22+stock!L22*stock_position!V22 -> 41819488 | D31: =(B31+C31)-F$241 -> 22991219 | E31: =(futures!F22-futures_position!$K$16)*300*25000 -> 1863750 | F31: =L104 -> 52221.79 | G31: 4424 | H31: =G31+F31 -> 56645.79 | I31: =O104 -> 85044.73 | L31: =E$213+B31+C31-(F$213-2659617.98)+E31-H31-I31 -> 1.1659366e+08 | M31: =B104 -> 1.1659366e+08 | N31: =L31-M31 -> -0.0080922097 | O31: =stock!AG22*stock_position!AX22/M31 -> 0.17424165
A32: 46134 | B32: =stock!AG23*stock_position!AX23+stock!AB23*stock_position!BJ23+stock!AH23*stock_position!AZ23+stock!AC23*stock_position!BN23+stock!AD23*stock_position!BL23 -> 61653787 | C32: =stock!N23*stock_position!Z23+stock!O23*stock_position!AB23+stock!I23*stock_position!P23+stock!J23*stock_position!R23+stock!K23*stock_position!T23+stock!P23*stock_position!AD23+stock!Q23*stock_position!AF23+stock!L23*stock_position!V23 -> 43472920 | D32: =(B32+C32)-F$241 -> 24255315 | E32: =(futures!F23-futures_position!$K$16)*300*25000 -> 1942500 | F32: =L105 -> 52221.79 | G32: 4424 | H32: =G32+F32 -> 56645.79 | I32: =O105 -> 85044.73 | L32: =E$213+B32+C32-(F$213-2659617.98)+E32-H32-I32 -> 1.1793651e+08 | M32: =B105 -> 1.1793651e+08 | N32: =L32-M32 -> 0.010158733 | O32: =stock!AG23*stock_position!AX23/M32 -> 0.17198428
A33: 46135 | B33: =stock!AG24*stock_position!AX24+stock!AB24*stock_position!BJ24+stock!AH24*stock_position!AZ24+stock!AC24*stock_position!BN24+stock!AD24*stock_position!BL24 -> 57912942 | C33: =stock!N24*stock_position!Z24+stock!O24*stock_position!AB24+stock!I24*stock_position!P24+stock!J24*stock_position!R24+stock!K24*stock_position!T24+stock!P24*stock_position!AD24+stock!Q24*stock_position!AF24+stock!L24*stock_position!V24 -> 42494392 | D33: =(B33+C33)-F$241 -> 19535942 | E33: =(futures!F24-futures_position!$K$16)*300*25000 -> 1488750 | F33: =L106 -> 52221.79 | G33: 4424 | H33: =G33+F33 -> 56645.79 | I33: =O106 -> 85044.73 | L33: =E$213+B33+C33-(F$213-2659617.98)+E33-H33-I33 -> 1.1276338e+08 | M33: 112763383 | N33: =L33-M33 -> 0.47943635 | O33: =stock!AG24*stock_position!AX24/M33 -> 0.16498752
A34: 46136 | B34: =stock!AG25*stock_position!AX25+stock!AB25*stock_position!BJ25+stock!AH25*stock_position!AZ25+stock!AC25*stock_position!BN25+stock!AD25*stock_position!BL25 -> 60490612 | C34: =stock!N25*stock_position!Z25+stock!O25*stock_position!AB25+stock!I25*stock_position!P25+stock!J25*stock_position!R25+stock!K25*stock_position!T25+stock!P25*stock_position!AD25+stock!Q25*stock_position!AF25+stock!L25*stock_position!V25 -> 43206838 | D34: =(B34+C34)-F$241 -> 22826058 | E34: =(futures!F25-futures_position!$K$16)*300*25000 -> 1646250 | F34: =L107 -> 52221.79 | G34: 4424 | H34: =G34+F34 -> 56645.79 | I34: =O107 -> 85044.73 | L34: =E$213+B34+C34-(F$213-2659617.98)+E34-H34-I34 -> 1.16211e+08 | M34: 116210999 | N34: =L34-M34 -> 0.40539683 | O34: =stock!AG25*stock_position!AX25/M34 -> 0.17642367
A35: 46137 | B35: =C152 -> 0424股票淨值 | C35: =D152 -> 1.0369745e+08
A36: 46138
A37: 46139 | B37: =stock!AE26*stock_position!BP26+stock!AG26*stock_position!AX26+stock!AH26*stock_position!AZ26+stock!AI26*stock_position!BB26 -> 58335339 | C37: =stock!N26*stock_position!Z26+stock!O26*stock_position!AB26+stock!I26*stock_position!P26+stock!J26*stock_position!R26+stock!K26*stock_position!T26+stock!P26*stock_position!AD26+stock!Q26*stock_position!AF26+stock!L26*stock_position!V26+stock!R26*stock_position!AH26 -> 48173039 | D37: =(B37+C37)-F$241 -> 25636986 | E37: =(futures!F26-futures_position!$K$16)*300*25000 -> 1500000 | F37: =H37-G37 -> 65551.01 | G37: 4424 | H37: 69975.01 | I37: 128354.12 | L37: =E$213+B37+C37-(F$213+2400656)+E37-H37-I37 -> 1.1375876e+08 | M37: 113758764 | N37: =L37-M37 -> 0.82358323 | O37: =stock!AG26*stock_position!AX26/M37 -> 0.21172665
A38: 46140 | B38: =stock!AE27*stock_position!BP27+stock!AG27*stock_position!AX27+stock!AH27*stock_position!AZ27+stock!AI27*stock_position!BB27 -> 60304515 | C38: =stock!N27*stock_position!Z27+stock!O27*stock_position!AB27+stock!I27*stock_position!P27+stock!J27*stock_position!R27+stock!K27*stock_position!T27+stock!P27*stock_position!AD27+stock!Q27*stock_position!AF27+stock!L27*stock_position!V27+stock!R27*stock_position!AH27 -> 46924824 | D38: =(B38+C38)-F$241 -> 26357947 | E38: =(futures!F27-futures_position!$K$16)*300*25000 -> 1548750 | F38: =H38-G38 -> 65551.01 | G38: 4424 | H38: 69975.01 | I38: 128354.12 | L38: =E$213+B38+C38-(F$213+2399656)+E38-H38-I38 -> 1.1452948e+08 | M38: 114529475 | N38: =L38-M38 -> 1.0687298 | O38: =stock!AG27*stock_position!AX27/M38 -> 0.230539
A39: 46141 | B39: =stock!AE28*stock_position!BP28+stock!AG28*stock_position!AX28+stock!AH28*stock_position!AZ28+stock!AI28*stock_position!BB28 -> 62822397 | C39: =stock!N28*stock_position!Z28+stock!O28*stock_position!AB28+stock!I28*stock_position!P28+stock!J28*stock_position!R28+stock!K28*stock_position!T28+stock!P28*stock_position!AD28+stock!Q28*stock_position!AF28+stock!L28*stock_position!V28+stock!R28*stock_position!AH28 -> 49516893 | D39: =(B39+C39)-F$241 -> 31467899 | E39: =(futures!F28-futures_position!$K$16)*300*25000 -> 1432500 | F39: =H39-G39 -> 65551.01 | G39: 4424 | H39: 69975.01 | I39: 128354.12 | L39: =E$213+B39+C39-(F$213+2399656)+E39-H39-I39 -> 1.1952318e+08 | M39: 119523177 | N39: =L39-M39 -> 0.66265731 | O39: =stock!AG28*stock_position!AX28/M39 -> 0.24377032
A40: 46142 | B40: =stock!AE29*stock_position!BP29+stock!AG29*stock_position!AX29+stock!AH29*stock_position!AZ29+stock!AI29*stock_position!BB29 -> 64939875 | C40: =stock!N29*stock_position!Z29+stock!O29*stock_position!AB29+stock!I29*stock_position!P29+stock!J29*stock_position!R29+stock!K29*stock_position!T29+stock!P29*stock_position!AD29+stock!Q29*stock_position!AF29+stock!L29*stock_position!V29+stock!R29*stock_position!AH29 -> 51296214 | D40: =(B40+C40)-F$241 -> 35364696 | E40: =(futures!F29-futures_position!$K$16)*300*25000 -> 1601250 | F40: =H40-G40 -> 65551.01 | G40: 4424 | H40: 69975.01 | I40: 128354.12 | L40: =E$213+B40+C40-(F$213+2399656)+E40-H40-I40 -> 1.2358873e+08 | M40: 123588724 | N40: =L40-M40 -> 1.1838636 | O40: =stock!AG29*stock_position!AX29/M40 -> 0.25656345
...

Sheet stock
A1: date | B1: RKLB_p | C1: LASR_p | D1: AR_p | E1: NTR_p | F1: RRC_p | G1: ET_p | H1: GSAT_p | I1: SQM_p | J1: OII_p | K1: SLB_p | L1: SIMO_p | M1: FCEL_p | N1: LUNR_p | O1: AMSC_p | P1: SMTC_p | Q1: CMBT_p | R1: CDNS_p | S1: DINO_p | T1: SYNA_p | U1: MX_p | V1: PRLB_p | W1: CSIQ_p | X1: SHLS_p | Y1: OUST_p | Z1: 2454_p | AA1: 1582_p | AB1: 8086_p | AC1: 3450_p | AD1: 4916_p | AE1: 3035_p | AF1: 2449_p | AG1: 8064_p | AH1: 3711_p | AI1: 2049_p | AJ1: 3406_p
A2: 46104 | B2: 68 | C2: 69.95 | D2: 42.56 | E2: 72.86 | F2: 43.7 | N2: 20.31 | Z2: ='stock TW'!B2/parameters!I2 -> 50.765386 | AB2: ='stock TW'!E2/parameters!I2 -> 3.7956888 | AF2: ='stock TW'!H2/parameters!I2 -> 8.9347079 | AG2: ='stock TW'!I2/parameters!I2 -> 2.2118088 | AH2: ='stock TW'!J2/parameters!I2 -> 10.293658
A3: 46105 | B3: 66.07 | C3: 71.56 | D3: 43.37 | E3: 76.82 | F3: 45.94 | N3: 17.92 | Z3: ='stock TW'!B3/parameters!I3 -> 51.201011 | AB3: ='stock TW'!E3/parameters!I3 -> 3.8242731 | AF3: ='stock TW'!H3/parameters!I3 -> 8.8021492 | AG3: ='stock TW'!I3/parameters!I3 -> 2.0417193 | AH3: ='stock TW'!J3/parameters!I3 -> 10.50885
A4: 46106 | B4: 72.88 | C4: 71.75 | D4: 44.67 | E4: 76.62 | F4: 46.59 | N4: 20.55 | Z4: ='stock TW'!B4/parameters!I4 -> 51.379638 | AB4: ='stock TW'!E4/parameters!I4 -> 4.012052 | AF4: ='stock TW'!H4/parameters!I4 -> 9.1500159 | AG4: ='stock TW'!I4/parameters!I4 -> 2.1566762 | AH4: ='stock TW'!J4/parameters!I4 -> 11.163971
A5: 46107 | B5: 65.94 | C5: 63.86 | D5: 44.33 | E5: 73.69 | F5: 46.83 | N5: 19.23 | Z5: ='stock TW'!B5/parameters!I5 -> 50.508259 | AB5: ='stock TW'!E5/parameters!I5 -> 3.9707751 | AF5: ='stock TW'!H5/parameters!I5 -> 9.1486658 | AG5: ='stock TW'!I5/parameters!I5 -> 2.3729352 | AH5: ='stock TW'!J5/parameters!I5 -> 11.404066
A6: 46108 | B6: 60.93 | C6: 64.32 | D6: 45.15 | E6: 75.65 | F6: 47.65 | N6: 17.52 | Z6: ='stock TW'!B6/parameters!I6 -> 50.349428 | AB6: ='stock TW'!E6/parameters!I6 -> 4.113723 | AF6: ='stock TW'!H6/parameters!I6 -> 8.8468869 | AG6: ='stock TW'!I6/parameters!I6 -> 2.2426938 | AH6: ='stock TW'!J6/parameters!I6 -> 11.229352
A7: 46111 | D7: 44.23 | E7: 76.55 | F7: 46.21 | G7: 19.59 | I7: 80.92 | N7: 16.35 | O7: 32.21 | AA7: ='stock TW'!C7/parameters!I7 -> 3.2278481 | AB7: ='stock TW'!E7/parameters!I7 -> 3.971519 | AF7: ='stock TW'!H7/parameters!I7 -> 8.6075949 | AG7: ='stock TW'!I7/parameters!I7 -> 2.1107595 | AH7: ='stock TW'!J7/parameters!I7 -> 11.186709
A8: 46112 | D8: 42.44 | E8: 75.46 | F8: 45.18 | G8: 19.3 | I8: 80.94 | N8: 18.56 | O8: 33.85 | AA8: ='stock TW'!C8/parameters!I8 -> 3.120747 | AB8: ='stock TW'!E8/parameters!I8 -> 3.7347682 | AF8: ='stock TW'!H8/parameters!I8 -> 8.2608008 | AG8: ='stock TW'!I8/parameters!I8 -> 2.0034816 | AH8: ='stock TW'!J8/parameters!I8 -> 10.397215
A9: 46113 | D9: 40.86 | E9: 74.56 | F9: 43.5 | G9: 19.02 | I9: 81.82 | N9: 20.24 | O9: 33.85 | AA9: ='stock TW'!C9/parameters!I9 -> 3.4220532 | AB9: ='stock TW'!E9/parameters!I9 -> 3.8973384 | AF9: ='stock TW'!H9/parameters!I9 -> 8.8878327 | AG9: ='stock TW'!I9/parameters!I9 -> 2.0437262 | AH9: ='stock TW'!J9/parameters!I9 -> 11.43853
A10: 46114 | D10: 40.45 | E10: 75.47 | F10: 43.45 | G10: 18.93 | I10: 83.21 | N10: 23.99 | O10: 32.09 | AA10: ='stock TW'!C10/parameters!I10 -> 3.3248892 | AB10: ='stock TW'!E10/parameters!I10 -> 3.9740342 | AF10: ='stock TW'!H10/parameters!I10 -> 8.2013933 | AG10: ='stock TW'!I10/parameters!I10 -> 2.0899303 | AH10: ='stock TW'!J10/parameters!I10 -> 11.431286
A11: 46118 | D11: 40.36 | E11: 75.81 | F11: 43.67 | G11: 18.96 | I11: 80.45 | N11: 22.92 | O11: 32.62 | AA11: ='stock TW'!C10/parameters!I10 -> 3.3248892 | AB11: ='stock TW'!E10/parameters!I10 -> 3.9740342 | AF11: ='stock TW'!H10/parameters!I10 -> 8.2013933 | AG11: ='stock TW'!I10/parameters!I10 -> 2.0899303 | AH11: ='stock TW'!J10/parameters!I10 -> 11.431286 | AK11: 由於0406沒有匯率更新.股價換算直接照0402的價值
A12: 46119 | D12: 40.36 | E12: 76.88 | F12: 43.33 | G12: 19.12 | I12: 78.52 | N12: 22.73 | O12: 31.54 | AA12: ='stock TW'!C12/parameters!I12 -> 3.2846373 | AB12: ='stock TW'!E12/parameters!I12 -> 4.3169519 | AF12: ='stock TW'!H12/parameters!I12 -> 8.3836456 | AG12: ='stock TW'!I12/parameters!I12 -> 2.0270904 | AH12: ='stock TW'!J12/parameters!I12 -> 11.011355 | AK12: 請從這行開始複製公式
A13: 46120 | D13: 39.17 | E13: 74.88 | F13: 43.33 | G13: 19.08 | I13: 82.48 | N13: 23.39 | O13: 33.02 | AA13: ='stock TW'!C13/parameters!I13 -> 3.3091711 | AB13: ='stock TW'!E13/parameters!I13 -> 4.5855657 | AF13: ='stock TW'!H13/parameters!I13 -> 8.8244564 | AG13: ='stock TW'!I13/parameters!I13 -> 2.2439332 | AH13: ='stock TW'!J12/parameters!I13 -> 11.093602
A14: 46121 | D14: 38.21 | E14: 72.78 | F14: 42.93 | G14: 19.09 | I14: 82.17 | N14: 21.97 | O14: 36.15 | AA14: ='stock TW'!C14/parameters!I14 -> 3.1489362 | AB14: ='stock TW'!E14/parameters!I14 -> 4.4917258 | AF14: ='stock TW'!H14/parameters!I14 -> 8.6682427 | AG14: ='stock TW'!I14/parameters!I14 -> 2.4680851 | AH14: ='stock TW'!J14/parameters!I14 -> 12.356186
A15: 46122 | D15: 37.89 | E15: 73.75 | F15: 42.84 | G15: 19.19 | I15: 82.12 | N15: 23.57 | O15: 37.71 | AA15: ='stock TW'!C15/parameters!I15 -> 3.1024577 | AB15: ='stock TW'!E15/parameters!I15 -> 4.6121928 | AF15: ='stock TW'!H15/parameters!I15 -> 8.8573252 | AG15: ='stock TW'!I15/parameters!I15 -> 2.4832429 | AH15: ='stock TW'!J15/parameters!I15 -> 12.543888
A16: 46125 | E16: 74.38 | F16: 41.9 | G16: 18.85 | H16: 72.89 | I16: 87.63 | N16: 24.41 | O16: 37.81 | AA16: ='stock TW'!C16/parameters!I16 -> 3.3911797 | AB16: ='stock TW'!E16/parameters!I16 -> 4.4101258 | AC16: ='stock TW'!D16/parameters!I16 -> 9.8551186 | AG16: ='stock TW'!I16/parameters!I16 -> 2.6428913 | AH16: ='stock TW'!J16/parameters!I16 -> 13.294061
A17: 46126 | E17: 73.62 | F17: 40.69 | G17: 18.73 | H17: 79.91 | I17: 88.93 | N17: 23.67 | O17: 39.45 | AA17: ='stock TW'!C17/parameters!I17 -> 3.2385466 | AB17: ='stock TW'!E17/parameters!I17 -> 4.2969984 | AC17: ='stock TW'!D17/parameters!I17 -> 9.9368088 | AG17: ='stock TW'!I17/parameters!I17 -> 2.3949447 | AH17: ='stock TW'!J17/parameters!I17 -> 13.396524
A18: 46127 | E18: 73.35 | F18: 41.22 | G18: 18.71 | H18: 80.64 | I18: 87.62 | N18: 23.88 | O18: 37.74 | AA18: ='stock TW'!C18/parameters!I18 -> 3.2645223 | AB18: ='stock TW'!E18/parameters!I18 -> 4.2886862 | AC18: ='stock TW'!D18/parameters!I18 -> 11.057769 | AG18: ='stock TW'!I18/parameters!I18 -> 2.4035846 | AH18: ='stock TW'!J18/parameters!I18 -> 14.290286
A19: 46128 | E19: 74.53 | F19: 42.27 | G19: 18.87 | H19: 80.03 | I19: 95.31 | N19: 27.28 | O19: 37.97 | AA19: ='stock TW'!C19/parameters!I19 -> 3.257904 | AB19: ='stock TW'!E19/parameters!I19 -> 4.5257583 | AC19: ='stock TW'!D19/parameters!I19 -> 10.945274 | AG19: ='stock TW'!I19/parameters!I19 -> 2.4169475 | AH19: ='stock TW'!J19/parameters!I19 -> 14.443909
A20: 46129 | E20: 70.62 | F20: 41.71 | G20: 18.86 | H20: 80.02 | I20: 88.8 | N20: 27.58 | O20: 39.72 | AA20: ='stock TW'!C20/parameters!I20 -> 3.1815266 | AB20: ='stock TW'!E20/parameters!I20 -> 4.7626684 | AC20: ='stock TW'!D20/parameters!I20 -> 11.738294 | AG20: ='stock TW'!I20/parameters!I20 -> 2.5016036 | AH20: ='stock TW'!J20/parameters!I20 -> 14.175754
A21: 46132 | I21: 88.42 | J21: 37.1 | K21: 52.2 | L21: 138.7 | N21: 27.52 | O21: 40.73 | P21: 105.91 | Q21: 13.34 | AB21: ='stock TW'!E21/parameters!I21 -> 4.7649301 | AC21: ='stock TW'!D21/parameters!I21 -> 12.166455 | AD21: ='stock TW'!F21/parameters!I21 -> 2.1759848 | AG21: ='stock TW'!I21/parameters!I21 -> 2.6524778 | AH21: ='stock TW'!J21/parameters!I21 -> 14.660102
A22: 46133 | I22: 87.22 | J22: 37.82 | K22: 52.77 | L22: 142.45 | N22: 27.82 | O22: 41.93 | P22: 103.48 | Q22: 12.89 | AB22: ='stock TW'!E22/parameters!I22 -> 4.6422893 | AC22: ='stock TW'!D22/parameters!I22 -> 12.082671 | AD22: ='stock TW'!F22/parameters!I22 -> 2.136725 | AG22: ='stock TW'!I22/parameters!I22 -> 2.6486486 | AH22: ='stock TW'!J22/parameters!I22 -> 15.007949
A23: 46134 | I23: 86.95 | J23: 38.47 | K23: 54.35 | L23: 141.95 | N23: 29.94 | O23: 48.15 | P23: 103.48 | Q23: 12.97 | AB23: ='stock TW'!E23/parameters!I23 -> 4.7460317 | AC23: ='stock TW'!D23/parameters!I23 -> 11.539683 | AD23: ='stock TW'!F23/parameters!I23 -> 2.2063492 | AG23: ='stock TW'!I23/parameters!I23 -> 2.6444444 | AH23: ='stock TW'!J23/parameters!I23 -> 14.761905
A24: 46135 | I24: 85.45 | J24: 38.01 | K24: 54.74 | L24: 142 | N24: 27.56 | O24: 46.15 | P24: 105.34 | Q24: 12.87 | AB24: ='stock TW'!E24/parameters!I24 -> 4.2906903 | AC24: ='stock TW'!D24/parameters!I24 -> 10.560481 | AD24: ='stock TW'!F24/parameters!I24 -> 2.0930969 | AG24: ='stock TW'!I24/parameters!I24 -> 2.4255858 | AH24: ='stock TW'!J24/parameters!I24 -> 14.708676
A25: 46136 | I25: 88.79 | J25: 37.35 | K25: 56.15 | L25: 153.46 | N25: 25.53 | O25: 49.48 | P25: 109.79 | Q25: 12.85 | AB25: ='stock TW'!E25/parameters!I25 -> 4.3809524 | AC25: ='stock TW'!D25/parameters!I25 -> 10.095238 | AD25: ='stock TW'!F25/parameters!I25 -> 2.0888889 | AG25: ='stock TW'!I25/parameters!I25 -> 2.6730159 | AH25: ='stock TW'!J25/parameters!I25 -> 15.746032
A26: 46139 | I26: 91.29 | J26: 37.99 | K26: 55.23 | L26: 147.54 | N26: 26.2 | O26: 49.64 | P26: 101.29 | Q26: 13.17 | R26: 336.54 | AE26: ='stock TW'!G26/parameters!I26 -> 5.9243964 | AG26: ='stock TW'!I26/parameters!I26 -> 2.4936468 | AH26: ='stock TW'!J26/parameters!I26 -> 15.740152 | AI26: ='stock TW'!K26/parameters!I26 -> 9.3710292
A27: 46140 | I27: 89.42 | J27: 37.56 | K27: 55.65 | L27: 149.18 | N27: 24.58 | O27: 47.5 | P27: 94.4 | Q27: 13.24 | R27: 325.31 | AE27: ='stock TW'!G27/parameters!I27 -> 5.5907507 | AG27: ='stock TW'!I27/parameters!I27 -> 2.7336079 | AH27: ='stock TW'!J27/parameters!I27 -> 15.69528 | AI27: ='stock TW'!K27/parameters!I27 -> 9.5343681
A28: 46141 | I28: 91.01 | J28: 36 | K28: 55.7 | L28: 217.5 | N28: 24.79 | O28: 47.7 | P28: 98.29 | Q28: 13.44 | R28: 329.95 | AE28: ='stock TW'!G28/parameters!I28 -> 5.3560076 | AG28: ='stock TW'!I28/parameters!I28 -> 3.0165289 | AH28: ='stock TW'!J28/parameters!I28 -> 15.527654 | AI28: ='stock TW'!K28/parameters!I28 -> 9.806103
A29: 46142 | I29: 92.17 | J29: 37.54 | K29: 56.88 | L29: 218.78 | N29: 25.35 | O29: 53.54 | P29: 105.05 | Q29: 13.77 | R29: 329.59 | AE29: ='stock TW'!G29/parameters!I29 -> 5.3030303 | AG29: ='stock TW'!I29/parameters!I29 -> 3.2828283 | AH29: ='stock TW'!J29/parameters!I29 -> 15.088384 | AI29: ='stock TW'!K29/parameters!I29 -> 9.8642677
A30: 46143 | I30: 92.68 | J30: 37.07 | K30: 56.92 | L30: 234.52 | N30: 25.62 | O30: 52.51 | P30: 107.81 | Q30: 13.73 | R30: 340.94 | AE30: ='stock TW'!G29/parameters!I29 -> 5.3030303 | AG30: ='stock TW'!I29/parameters!I29 -> 3.2828283 | AH30: ='stock TW'!J29/parameters!I29 -> 15.088384 | AI30: ='stock TW'!K29/parameters!I29 -> 9.8642677 | AK30: 由於0501沒有匯率更新.股價換算直接照0430的價值
A31: 46146 | I31: 89.75 | J31: 37.35 | K31: 55.63 | L31: 227.16 | N31: 25.35 | O31: 50.3 | P31: 107.1 | Q31: 14.25 | R31: 349.51 | AF31: ='stock TW'!H31/parameters!I30 -> 10.50885 | AG31: ='stock TW'!I31/parameters!I30 -> 3.6030341 | AH31: ='stock TW'!J31/parameters!I30 -> 16.59292 | AI31: ='stock TW'!K31/parameters!I30 -> 10.066372 | AK31: 請從這行開始複製公式
A32: 46147 | I32: 92.64 | J32: 37.66 | K32: 56 | L32: 238.41 | N32: 24.8 | O32: 55.01 | P32: 112.98 | Q32: 15.13 | R32: 353.63 | AF32: ='stock TW'!H32/parameters!I31 -> 11.198988 | AG32: ='stock TW'!I32/parameters!I31 -> 3.9544448 | AH32: ='stock TW'!J32/parameters!I31 -> 16.45049 | AI32: ='stock TW'!K32/parameters!I31 -> 10.155014
A33: 46148 | I33: 93.46 | J33: 37.07 | K33: 55.16 | L33: 244.95 | N33: 26.33 | O33: 57.07 | P33: 119.19 | Q33: 14.78 | R33: 354.9 | AF33: ='stock TW'!H33/parameters!I32 -> 10.435197 | AG33: ='stock TW'!I33/parameters!I32 -> 3.5736976 | AH33: ='stock TW'!J33/parameters!I32 -> 16.645489 | AI33: ='stock TW'!K33/parameters!I32 -> 10.022236
A34: 46149 | I34: 91.6 | J34: 36.58 | K34: 53 | L34: 242.71 | N34: 24.11 | O34: 53.22 | P34: 121.5 | Q34: 14.76 | R34: 356.9 | AF34: ='stock TW'!H34/parameters!I33 -> 10.796178 | AG34: ='stock TW'!I34/parameters!I33 -> 3.4394904 | AH34: ='stock TW'!J34/parameters!I33 -> 17.197452 | AI34: ='stock TW'!K34/parameters!I33 -> 10.127389
A35: 46150 | I35: 91.39 | J35: 36.54 | K35: 53.27 | L35: 253.59 | N35: 28.97 | O35: 55.19 | P35: 121.81 | Q35: 14.83 | R35: 362.7 | AF35: ='stock TW'!H35/parameters!I34 -> 9.8950048 | AG35: ='stock TW'!I35/parameters!I34 -> 3.2930321 | AH35: ='stock TW'!J35/parameters!I34 -> 16.417436 | AI35: ='stock TW'!K35/parameters!I34 -> 10.165447
A36: 46153 | L36: 262.05 | M36: 15.94 | N36: 32.42 | O36: 58.72 | P36: 136.53 | Q36: 14.77 | R36: 364.2 | S36: 72.81 | T36: 126.55 | AF36: ='stock TW'!H36/parameters!I35 -> 9.5351799 | AG36: ='stock TW'!I36/parameters!I35 -> 3.6134989 | AH36: ='stock TW'!J36/parameters!I35 -> 17.096466 | AI36: ='stock TW'!K36/parameters!I35 -> 11.174785
A37: 46154 | L37: 258.71 | M37: 17.09 | N37: 32.09 | O37: 54.51 | P37: 132.08 | Q37: 15.15 | R37: 358.04 | S37: 71.34 | T37: 119.59 | AF37: ='stock TW'!H37/parameters!I36 -> 9.5555556 | AG37: ='stock TW'!I37/parameters!I36 -> 3.7142857 | AH37: ='stock TW'!J37/parameters!I36 -> 17.619048 | AI37: ='stock TW'!K37/parameters!I36 -> 11.666667
A38: 46155 | L38: 269.87 | M38: 19.92 | N38: 35.68 | O38: 55.73 | P38: 139.74 | Q38: 14.98 | R38: 354.55 | S38: 69.38 | T38: 131.06 | AF38: ='stock TW'!H38/parameters!I37 -> 9.6671949 | AG38: ='stock TW'!I38/parameters!I37 -> 3.7559429 | AH38: ='stock TW'!J38/parameters!I37 -> 17.369255 | AI38: ='stock TW'!K38/parameters!I37 -> 11.55309
A39: 46156 | L39: 263.85 | M39: 21.6 | N39: 36.52 | O39: 54.7 | P39: 141.16 | Q39: 14.9 | R39: 352.84 | S39: 68.71 | T39: 129.78 | AF39: ='stock TW'!H39/parameters!I38 -> 9.3938432 | AG39: ='stock TW'!I39/parameters!I38 -> 3.665503 | AH39: ='stock TW'!J39/parameters!I38 -> 17.391304 | AI39: ='stock TW'!K39/parameters!I38 -> 11.885116
A40: 46157 | L40: 259.59 | M40: 21.36 | N40: 33.89 | O40: 55.06 | P40: 137.64 | Q40: 14.94 | R40: 347.24 | S40: 70.01 | T40: 128.23 | AF40: ='stock TW'!H40/parameters!I39 -> 9.4958783 | AG40: ='stock TW'!I40/parameters!I39 -> 3.8046925 | AH40: ='stock TW'!J40/parameters!I39 -> 17.343056 | AI40: ='stock TW'!K40/parameters!I39 -> 12.444515
...

Sheet stock TW
A1: date | B1: 2454_p | C1: 1582_p | D1: 3450_p | E1: 8086_p | F1: 4916_p | G1: 3035_p | H1: 2449_p | I1: 8064_p | J1: 3711_p | K1: 2049_p | L1: 3406_p
A2: 46104 | B2: 1625 | E2: 121.5 | H2: 286 | I2: 70.8 | J2: 329.5
A3: 46105 | B3: 1620 | E3: 121 | H3: 278.5 | I3: 64.6 | J3: 332.5
A4: 46106 | B4: 1620 | E4: 126.5 | H4: 288.5 | I4: 68 | J4: 352
A5: 46107 | B5: 1590 | E5: 125 | H5: 288 | I5: 74.7 | J5: 359
A6: 46108 | B6: 1585 | E6: 129.5 | H6: 278.5 | I6: 70.6 | J6: 353.5
A7: 46111 | C7: 102 | E7: 125.5 | H7: 272 | I7: 66.7 | J7: 353.5
A8: 46112 | C8: 98.6 | E8: 118 | H8: 261 | I8: 63.3 | J8: 328.5
A9: 46113 | C9: 108 | E9: 123 | H9: 280.5 | I9: 64.5 | J9: 361
A10: 46114 | C10: 105 | E10: 125.5 | H10: 259 | I10: 66 | J10: 361
A11: 46118 | C11: 105 | E11: 125.5 | H11: 259 | I11: 66 | J11: 361
A12: 46119 | C12: 105 | E12: 138 | H12: 268 | I12: 64.8 | J12: 352
A13: 46120 | C13: 105 | E13: 145.5 | H13: 280 | I13: 71.2 | J13: 383
A14: 46121 | C14: 99.9 | E14: 142.5 | H14: 275 | I14: 78.3 | J14: 392
A15: 46122 | C15: 97.2 | E15: 144.5 | H15: 277.5 | I15: 77.8 | J15: 393
A16: 46125 | C16: 106.5 | D16: 309.5 | E16: 138.5 | I16: 83 | J16: 417.5
A17: 46126 | C17: 102.5 | D17: 314.5 | E17: 136 | I17: 75.8 | J17: 424
A18: 46127 | C18: 102 | D18: 345.5 | E18: 134 | I18: 75.1 | J18: 446.5
A19: 46128 | C19: 101.5 | D19: 341 | E19: 141 | I19: 75.3 | J19: 450
A20: 46129 | C20: 99.2 | D20: 366 | E20: 148.5 | I20: 78 | J20: 442
A21: 46132 | D21: 383 | E21: 150 | F21: 68.5 | I21: 83.5 | J21: 461.5
A22: 46133 | D22: 380 | E22: 146 | F22: 67.2 | I22: 83.3 | J22: 472
A23: 46134 | D23: 363.5 | E23: 149.5 | F23: 69.5 | I23: 83.3 | J23: 465
A24: 46135 | D24: 333.5 | E24: 135.5 | F24: 66.1 | I24: 76.6 | J24: 464.5
A25: 46136 | D25: 318 | E25: 138 | F25: 65.8 | I25: 84.2 | J25: 496
A26: 46139 | F26: 62.4 | G26: 186.5 | I26: 78.5 | J26: 495.5 | K26: 295
A27: 46140 | G27: 176.5 | I27: 86.3 | J27: 495.5 | K27: 301
A28: 46141 | G28: 168.5 | I28: 94.9 | J28: 488.5 | K28: 308.5
A29: 46142 | G29: 168 | I29: 104 | J29: 478 | K29: 312.5
A30: 46143 | G30: 168 | I30: 104 | J30: 478 | K30: 312.5
A31: 46146 | H31: 332.5 | I31: 114 | J31: 525 | K31: 318.5
A32: 46147 | H32: 354 | I32: 125 | J32: 520 | K32: 321
A33: 46148 | H33: 328.5 | I33: 112.5 | J33: 524 | K33: 315.5
A34: 46149 | H34: 339 | I34: 108 | J34: 540 | K34: 318
A35: 46150 | H35: 311 | I35: 103.5 | J35: 516 | K35: 319.5
A36: 46153 | H36: 299.5 | I36: 113.5 | J36: 537 | K36: 351
A37: 46154 | H37: 301 | I37: 117 | J37: 555 | K37: 367.5
A38: 46155 | H38: 305 | I38: 118.5 | J38: 548 | K38: 364.5
A39: 46156 | H39: 296 | I39: 115.5 | J39: 548 | K39: 374.5
A40: 46157 | H40: 299.5 | I40: 120 | J40: 547 | K40: 392.5
...

Sheet stock_position
A1: date | B1: RKLB | C1: RKLB_buyprice | D1: LASR | E1: LASR_buyprice | F1: AR | G1: AR_buyprice | H1: NTR | I1: NTR_buyprice | J1: RRC | K1: RRC_buyprice | L1: ET | M1: ET_buyprice | N1: GSAT | O1: GSAT_buyprice | P1: SQM | Q1: SQM_buyprice | R1: OII | S1: OII_buyprice | T1: SLB | U1: SLB_buyprice | V1: SIMO | W1: SIMO_buyprice | X1: FCEL | Y1: FCEL_buyprice | Z1: LUNR | AA1: LUNR_buyprice | AB1: AMSC | AC1: AMSC_buyprice | AD1: SMTC | AE1: SMTC_buyprice | AF1: CMBT | AG1: CMBT_buyprice | AH1: CDNS | AI1: CDNS_buyprice | AJ1: DINO | AK1: DINO_buyprice | AL1: SYNA | AM1: SYNA_buyprice | AN1: MX | AO1: MX_buyprice | AP1: PRLB | AQ1: PRLB_buyprice | AR1: CSIQ | AS1: CSIQ_buyprice | AT1: SHLS | AU1: SHLS_buyprice | AV1: OUST | AW1: OUST_buyprice | AX1: 8064 | AY1: 8064_buyprice | AZ1: 3711 | BA1: 3711_buyprice | BB1: 2049 | BC1: 2049_buyprice | BD1: 3406 | BE1: 3406_buyprice | BF1: 2454 | BG1: 2454_buyprice | BH1: 1582 | BI1: 1582_buyprice | BJ1: 8086 | BK1: 8086_buyprice | BL1: 4916 | BM1: 4916_buyprice | BN1: 3450 | BO1: 3450_buyprice | BP1: 3035 | BQ1: 3035_buyprice | BR1: 2449 | BS1: 2449_buyprice
A2: 46104 | B2: 146886 | C2: 68.08 | D2: 75187 | E2: 66.5 | F2: 119904 | G2: 41.7 | H2: 68101 | I2: 73.42 | J2: 228832 | K2: 43.7 | Z2: 271149 | AA2: 18.44 | AX2: 7670127 | AY2: 2.17 | AZ2: 1003448 | BA2: 9.97 | BF2: 196380 | BG2: 50.92 | BJ2: 1255294 | BK2: 3.98 | BR2: 1075966 | BS2: 9.3
A3: 46105 | B3: 146886 | D3: 75187 | F3: 119904 | H3: 68101 | J3: 228832 | Z3: 271149 | AX3: 7670127 | AZ3: 1003448 | BF3: 196380 | BJ3: 1255294 | BR3: 1075966
A4: 46106 | B4: 146886 | D4: 75187 | F4: 119904 | H4: 68101 | J4: 228832 | Z4: 271149 | AX4: 7670127 | AZ4: 1003448 | BF4: 196380 | BJ4: 1255294 | BR4: 1075966
A5: 46107 | B5: 146886 | D5: 75187 | F5: 119904 | H5: 68101 | J5: 228832 | Z5: 271149 | AX5: 7670127 | AZ5: 1003448 | BF5: 196380 | BJ5: 1255294 | BR5: 1075966
A6: 46108 | B6: 146886 | D6: 75187 | F6: 119904 | H6: 68101 | J6: 228832 | Z6: 271149 | AX6: 7670127 | AZ6: 1003448 | BF6: 196380 | BJ6: 1255294 | BR6: 1075966
A7: 46111 | B7: 0 | C7: 61.45 | D7: 0 | E7: 65.68 | F7: 119904 | H7: 68101 | J7: 228832 | L7: 235448 | M7: 19.77 | P7: 55460 | Q7: 83.93 | Z7: 271149 | AB7: 137431 | AC7: 33.87 | AX7: 7670127 | AZ7: 1003448 | BF7: 0 | BG7: 48.74 | BH7: 2826403 | BI7: 3.34 | BJ7: 1255294 | BR7: 1075966
A8: 46112 | F8: 119904 | H8: 68101 | J8: 228832 | L8: 235448 | P8: 55460 | Z8: 271149 | AB8: 137431 | AX8: 7670127 | AZ8: 1003448 | BH8: 2826403 | BJ8: 1255294 | BR8: 1075966
A9: 46113 | F9: 119904 | H9: 68101 | J9: 228832 | L9: 235448 | P9: 55460 | Z9: 271149 | AB9: 137431 | AX9: 7670127 | AZ9: 1003448 | BH9: 2826403 | BJ9: 1255294 | BR9: 1075966
A10: 46114 | F10: 119904 | H10: 68101 | J10: 228832 | L10: 235448 | P10: 55460 | Z10: 271149 | AB10: 137431 | AX10: 7670127 | AZ10: 1003448 | BH10: 2826403 | BJ10: 1255294 | BR10: 1075966
A11: 46118 | F11: 119904 | H11: 68101 | J11: 228832 | L11: 235448 | P11: 55460 | Z11: 271149 | AB11: 137431 | AX11: 7670127 | AZ11: 1003448 | BH11: 2826403 | BJ11: 1255294 | BR11: 1075966
A12: 46119 | F12: 119904 | H12: 68101 | J12: 228832 | L12: 235448 | P12: 55460 | Z12: 271149 | AB12: 137431 | AX12: 7670127 | AZ12: 1003448 | BH12: 2826403 | BJ12: 1255294 | BR12: 1075966
A13: 46120 | F13: 119904 | H13: 68101 | J13: 228832 | L13: 235448 | P13: 55460 | Z13: 271149 | AB13: 137431 | AX13: 7670127 | AZ13: 1003448 | BH13: 2826403 | BJ13: 1255294 | BR13: 1075966
A14: 46121 | F14: 119904 | H14: 68101 | J14: 228832 | L14: 235448 | P14: 55460 | Z14: 271149 | AB14: 137431 | AX14: 7670127 | AZ14: 1003448 | BH14: 2826403 | BJ14: 1255294 | BR14: 1075966
A15: 46122 | F15: 119904 | H15: 68101 | J15: 228832 | L15: 235448 | P15: 55460 | Z15: 271149 | AB15: 137431 | AX15: 7670127 | AZ15: 1003448 | BH15: 2826403 | BJ15: 1255294 | BR15: 1075966
A16: 46125 | F16: 0 | G16: 38.22 | H16: 68101 | J16: 228832 | L16: 235448 | N16: 63253 | O16: 72.45 | P16: 55460 | Z16: 271149 | AB16: 137431 | AX16: 7670127 | AZ16: 1003448 | BH16: 2826403 | BJ16: 1255294 | BN16: 981644 | BO16: 9.85 | BR16: 0 | BS16: 8.94
A17: 46126 | H17: 68101 | J17: 228832 | L17: 235448 | N17: 63253 | P17: 55460 | Z17: 271149 | AB17: 137431 | AX17: 7670127 | AZ17: 1003448 | BH17: 2826403 | BJ17: 1255294 | BN17: 981644
A18: 46127 | H18: 68101 | J18: 228832 | L18: 235448 | N18: 63253 | P18: 55460 | Z18: 271149 | AB18: 137431 | AX18: 7670127 | AZ18: 1003448 | BH18: 2826403 | BJ18: 1255294 | BN18: 981644
A19: 46128 | H19: 68101 | J19: 228832 | L19: 235448 | N19: 63253 | P19: 55460 | Z19: 271149 | AB19: 137431 | AX19: 7670127 | AZ19: 1003448 | BH19: 2826403 | BJ19: 1255294 | BN19: 981644
A20: 46129 | H20: 68101 | J20: 228832 | L20: 235448 | N20: 63253 | P20: 55460 | Z20: 271149 | AB20: 137431 | AX20: 7670127 | AZ20: 1003448 | BH20: 2826403 | BJ20: 1255294 | BN20: 981644
A21: 46132 | H21: 0 | I21: 71.3 | J21: 0 | K21: 41.45 | L21: 0 | M21: 18.9 | N21: 0 | O21: 79.9 | P21: 55460 | R21: 127171 | S21: 37.5 | T21: 91044 | U21: 52.38 | V21: 33636 | W21: 141.78 | Z21: 271149 | AB21: 137431 | AD21: 44349 | AE21: 107.53 | AF21: 363207 | AG21: 13.13 | AX21: 7670127 | AZ21: 1003448 | BH21: 0 | BI21: 3.24 | BJ21: 1255294 | BL21: 4202523 | BM21: 2.17 | BN21: 981644
A22: 46133 | P22: 55460 | R22: 127171 | T22: 91044 | V22: 33636 | Z22: 271149 | AB22: 137431 | AD22: 44349 | AF22: 363207 | AX22: 7670127 | AZ22: 1003448 | BJ22: 1255294 | BL22: 4202523 | BN22: 981644
A23: 46134 | P23: 55460 | R23: 127171 | T23: 91044 | V23: 33636 | Z23: 271149 | AB23: 137431 | AD23: 44349 | AF23: 363207 | AX23: 7670127 | AZ23: 1003448 | BJ23: 1255294 | BL23: 4202523 | BN23: 981644
A24: 46135 | P24: 55460 | R24: 127171 | T24: 91044 | V24: 33636 | Z24: 271149 | AB24: 137431 | AD24: 44349 | AF24: 363207 | AX24: 7670127 | AZ24: 1003448 | BJ24: 1255294 | BL24: 4202523 | BN24: 981644
A25: 46136 | P25: 55460 | R25: 127171 | T25: 91044 | V25: 33636 | Z25: 271149 | AB25: 137431 | AD25: 44349 | AF25: 363207 | AX25: 7670127 | AZ25: 1003448 | BJ25: 1255294 | BL25: 4202523 | BN25: 981644
A26: 46139 | P26: 55460 | R26: 127171 | T26: 91044 | V26: 33636 | Z26: 271149 | AB26: 137431 | AD26: 44349 | AF26: 363207 | AH26: 15113 | AI26: 330.82 | AX26: 9658851 | AY26: 2.82 | AZ26: 1003448 | BB26: 1064693 | BC26: 9.38 | BJ26: 0 | BK26: 4.47 | BL26: 0 | BM26: 2.1 | BN26: 0 | BO26: 10.18 | BP26: 1431012 | BQ26: 6.19
A27: 46140 | P27: 55460 | R27: 127171 | T27: 91044 | V27: 33636 | Z27: 271149 | AB27: 137431 | AD27: 44349 | AF27: 363207 | AH27: 15113 | AX27: 9658851 | AZ27: 1003448 | BB27: 1064693 | BP27: 1431012
A28: 46141 | P28: 55460 | R28: 127171 | T28: 91044 | V28: 33636 | Z28: 271149 | AB28: 137431 | AD28: 44349 | AF28: 363207 | AH28: 15113 | AX28: 9658851 | AZ28: 1003448 | BB28: 1064693 | BP28: 1431012
A29: 46142 | P29: 55460 | R29: 127171 | T29: 91044 | V29: 33636 | Z29: 271149 | AB29: 137431 | AD29: 44349 | AF29: 363207 | AH29: 15113 | AX29: 9658851 | AZ29: 1003448 | BB29: 1064693 | BP29: 1431012
A30: 46143 | P30: 55460 | R30: 127171 | T30: 91044 | V30: 33636 | Z30: 271149 | AB30: 137431 | AD30: 44349 | AF30: 363207 | AH30: 15113 | AX30: 9658851 | AZ30: 1003448 | BB30: 1064693 | BP30: 1431012
A31: 46146 | P31: 55460 | R31: 127171 | T31: 91044 | V31: 33636 | Z31: 271149 | AB31: 137431 | AD31: 44349 | AF31: 363207 | AH31: 15113 | AX31: 9658851 | AZ31: 1003448 | BB31: 1064693 | BP31: 0 | BQ31: 5.42 | BR31: 747088 | BS31: 10.38
A32: 46147 | P32: 55460 | R32: 127171 | T32: 91044 | V32: 33636 | Z32: 271149 | AB32: 137431 | AD32: 44349 | AF32: 363207 | AH32: 15113 | AX32: 9658851 | AZ32: 1003448 | BB32: 1064693 | BR32: 747088
A33: 46148 | P33: 55460 | R33: 127171 | T33: 91044 | V33: 33636 | Z33: 271149 | AB33: 137431 | AD33: 44349 | AF33: 363207 | AH33: 15113 | AX33: 9658851 | AZ33: 1003448 | BB33: 1064693 | BR33: 747088
A34: 46149 | P34: 55460 | R34: 127171 | T34: 91044 | V34: 33636 | Z34: 271149 | AB34: 137431 | AD34: 44349 | AF34: 363207 | AH34: 15113 | AX34: 9658851 | AZ34: 1003448 | BB34: 1064693 | BR34: 747088
A35: 46150 | P35: 55460 | R35: 127171 | T35: 91044 | V35: 33636 | Z35: 271149 | AB35: 137431 | AD35: 44349 | AF35: 363207 | AH35: 15113 | AX35: 9658851 | AZ35: 1003448 | BB35: 1064693 | BR35: 747088
A36: 46153 | P36: 0 | Q36: 93.87 | R36: 0 | S36: 36.96 | T36: 0 | U36: 53.67 | V36: 33636 | X36: 361765 | Y36: 13.63 | Z36: 271149 | AB36: 137431 | AD36: 44349 | AF36: 363207 | AH36: 15113 | AJ36: 67546 | AK36: 73 | AL36: 38737 | AM36: 127.29 | AX36: 9658851 | AZ36: 1003448 | BB36: 1064693 | BR36: 747088
A37: 46154 | V37: 33636 | X37: 361765 | Z37: 271149 | AB37: 137431 | AD37: 44349 | AF37: 363207 | AH37: 15113 | AJ37: 67546 | AL37: 38737 | AX37: 9658851 | AZ37: 1003448 | BB37: 1064693 | BR37: 747088
A38: 46155 | V38: 33636 | X38: 361765 | Z38: 271149 | AB38: 137431 | AD38: 44349 | AF38: 363207 | AH38: 15113 | AJ38: 67546 | AL38: 38737 | AX38: 9658851 | AZ38: 1003448 | BB38: 1064693 | BR38: 747088
A39: 46156 | V39: 33636 | X39: 361765 | Z39: 271149 | AB39: 137431 | AD39: 44349 | AF39: 363207 | AH39: 15113 | AJ39: 67546 | AL39: 38737 | AX39: 9658851 | AZ39: 1003448 | BB39: 1064693 | BR39: 747088
A40: 46157 | V40: 33636 | X40: 361765 | Z40: 271149 | AB40: 137431 | AD40: 44349 | AF40: 363207 | AH40: 15113 | AJ40: 67546 | AL40: 38737 | AX40: 9658851 | AZ40: 1003448 | BB40: 1064693 | BR40: 747088
...

Sheet futures
A1: date | B1: TX_p | C1: ES_p | D1: ALI_p | E1: GC_p | F1: HG_p
A2: 46104 | E2: 4407.3
A3: 46105 | E3: 4584
A4: 46106 | E4: 4535.5
A5: 46107 | E5: 4440.8
A6: 46108 | E6: 4508.6
A7: 46111 | E7: 4640.3
A8: 46112 | E8: 4765.6
A9: 46113 | E9: 4615.1
A10: 46114 | E10: 4702.7
A11: 46118 | E11: 4682
A12: 46119 | E12: 4835.9
A13: 46120 | E13: 4739.7
... A15: 46122 | E15: 4771
A16: 46125 | F16: 6.0135
A17: 46126 | F17: 6.095
A18: 46127 | F18: 6.118
A19: 46128 | F19: 6.0345
A20: 46129 | F20: 6.0815
A21: 46132 | F21: 6.044
A22: 46133 | F22: 6.0575
A23: 46134 | F23: 6.068
A24: 46135 | F24: 6.0075
A25: 46136 | F25: 6.0285
A26: 46139 | F26: 6.009
A27: 46140 | F27: 6.0155
... A47: 46168 | F47: 6.45

Sheet futures_position
A1: date | B1: TX | C1: TX_buyprice | D1: NQ | E1: NQ_buyprice | F1: ALI | G1: ALI_buyprice | H1: GC | I1: GC_buyprice | J1: HG | K1: HG_buyprice
A2: 46104 | H2: 100 | I2: 4450
A3: 46105 | H3: 100
A4: 46106 | H4: 100
A5: 46107 | H5: 100
A6: 46108 | H6: 100
A7: 46111 | H7: 100
A8: 46112 | H8: 100
A9: 46113 | H9: 100
A10: 46114 | H10: 100
A11: 46118 | H11: 100
A12: 46119 | H12: 100
A13: 46120 | H13: 100
A14: 46121 | H14: 100
A15: 46122 | H15: 100
A16: 46125 | H16: 0 | I16: 4704 | J16: 300 | K16: 5.809
A17: 46126 | J17: 300
A18: 46127 | J18: 300
A19: 46128 | J19: 300
A20: 46129 | J20: 300
A21: 46132 | J21: 300
A22: 46133 | J22: 300
A23: 46134 | J23: 300
A24: 46135 | J24: 300
A25: 46136 | J25: 300
A26: 46139 | J26: 300
A27: 46140 | J27: 300
A28: 46141 | J28: 300
... A47: 46168 | J47: 300

Sheet stock_events
A1: date | B1: RKLB_cd | C1: RKLB_sd | D1: LASR_cd | E1: LASR_sd | F1: AR_cd | G1: AR_sd | H1: NTR_cd | I1: NTR_sd | J1: RRC_cd | K1: RRC_sd | L1: ET_cd | M1: ET_sd | N1: GSAT_cd | O1: GSAT_sd | P1: SQM_cd | Q1: SQM_sd | R1: OII_cd | S1: OII_sd | T1: SLB_cd | U1: SLB_sd | V1: SIMO_cd | W1: SIMO_sd | X1: FCEL_cd | Y1: FCEL_sd | Z1: LUNR_cd | AA1: LUNR_sd | AB1: AMSC_cd | AC1: AMSC_sd | AD1: SMTC_cd | AE1: SMTC_sd | AF1: CMBT_cd | AG1: CMBT_sd | AH1: CDNS_cd | AI1: CDNS_sd | AJ1: DINO_cd | AK1: DINO_sd | AL1: SYNA_cd | AM1: SYNA_sd | AN1: MX_cd | AO1: MX_sd | AP1: PRLB_cd | AQ1: PRLD_sd | AR1: CSIQ_cd | AS1: CSIQ_sd | AT1: SHLS_cd | AU1: SHLS_sd | AV1: OUST_cd | AW1: OUST_sd | AX1: 2454_cd | AY1: 2454_sd | AZ1: 1582_cd | BA1: 1582_sd | BB1: 8086_cd | BC1: 8086_sd | BD1: 3035_cd | BE1: 3035_sd | BF1: 4916_cd | BG1: 4916_sd | BH1: 3450_cd | BI1: 3450_sd | BJ1: 2449_cd | BK1: 2449_sd | BL1: 8064_cd | BM1: 8064_sd | BN1: 3711_cd | BO1: 3711_sd | BP1: 2049_cd | BQ1: 2049_sd | BR1: 3406_cd | BS1: 3406_sd
A2: 46104
A3: 46105
A4: 46106
A5: 46107
A6: 46108
A7: 46111
A8: 46112
A9: 46113
A10: 46114
A11: 46119
A12: 46120
A13: 46121
... A32: 46148
A33: 46149 | V33: 0.5
A34: 46150 | P34: 1.03
A35: 46153 | AJ35: 0.5
A36: 46154
A37: 46155
A38: 46156
A39: 46157
A40: 46160
A41: 46161
A42: 46162
A43: 46163
A44: 46164
A45: 46167
A46: 46168
A47: 46169
... A49: 46171

Sheet bond
A1: date | B1: US10Y_p | C1: HY_BOND_p
A2: 46104
A3: 46105
A4: 46106
A5: 46107

Sheet bond_position
A1: date | B1: US10Y | C1: US10Y_buyprice | D1: HY_BOND | E1: HY_BOND_buyprice
A2: 46104
A3: 46105
A4: 46106
A5: 46107

Sheet bond_events
A1: date | B1: HY_BOND_coupon_payment
A2: 46104
A3: 46105
A4: 46106
A5: 46107

Sheet options
A1: date | B1: TXO_16000_P_p | C1: AAPL_180_C_p
A2: 46104
A3: 46105
A4: 46106
A5: 46107

Sheet options_position
A1: date | B1: TXO_16000_P | C1: TXO_16000_P_buyprice | D1: AAPL_180_P | E1: AAPL_180_P_buyprice
A2: 46104
A3: 46105
A4: 46106
A5: 46107
